src/output/live/wall_breakout/v2_ema/trades.jsonl
{"event": "STATE_NEW", "dt_utc": "2025-12-22T15:50:05Z", "note": "no state.json found; starting fresh", "schema_version": 1}
{"event": "BOOKS_SAVED", "dt_utc": "2025-12-22T16:00:05Z", "book_time": "2025-12-22T16:00:00Z", "ref_price": 4431.835, "buy_wall": 4440.0, "sell_wall": 4450.0, "attempts": 1, "schema_version": 1}
{"event": "CANDLES_SAVED", "dt_utc": "2025-12-22T16:00:09Z", "n_new": 20, "newest": "2025-12-22T15:59:00.000000000Z", "attempts": 1, "schema_version": 1}
{"event": "REPLAY_BATCH", "dt_utc": "2025-12-22T16:00:09Z", "note": "processing 20 new candles since 2025-12-22T15:39:00.000000000Z", "schema_version": 1}
{"event": "SHORT_CHECK", "dt_utc": "2025-12-22T16:00:09Z", "candle_time": "2025-12-22T15:40:00.000000000Z", "wall_time": "2025-12-22T15:40:00Z", "close": 4427.155, "ema": 4422.1418198648325, "ref_price": 4425.51, "buy_wall": 4440.0, "retests_buy": 1, "retests_required": 5, "break_buffer": 0.2, "min_ema_dist": 0.5, "max_wall_distance": 12.0, "reason": "EVAL", "mwd_ok": false, "ret_ok": false, "broken_down": true, "trend_ok": false, "dist_ref_to_wall": 14.489999999999782, "schema_version": 1}
{"event": "SHORT_CHECK", "dt_utc": "2025-12-22T16:00:09Z", "candle_time": "2025-12-22T15:41:00.000000000Z", "wall_time": "2025-12-22T15:40:00Z", "close": 4427.725, "ema": 4422.6493816953025, "ref_price": 4425.51, "buy_wall": 4440.0, "retests_buy": 2, "retests_required": 5, "break_buffer": 0.2, "min_ema_dist": 0.5, "max_wall_distance": 12.0, "reason": "EVAL", "mwd_ok": false, "ret_ok": false, "broken_down": true, "trend_ok": false, "dist_ref_to_wall": 14.489999999999782, "schema_version": 1}
{"event": "SHORT_CHECK", "dt_utc": "2025-12-22T16:00:09Z", "candle_time": "2025-12-22T15:42:00.000000000Z", "wall_time": "2025-12-22T15:40:00Z", "close": 4427.77, "ema": 4423.114892450275, "ref_price": 4425.51, "buy_wall": 4440.0, "retests_buy": 3, "retests_required": 5, "break_buffer": 0.2, "min_ema_dist": 0.5, "max_wall_distance": 12.0, "reason": "EVAL", "mwd_ok": false, "ret_ok": false, "broken_down": true, "trend_ok": false, "dist_ref_to_wall": 14.489999999999782, "schema_version": 1}
{"event": "SHORT_CHECK", "dt_utc": "2025-12-22T16:00:09Z", "candle_time": "2025-12-22T15:43:00.000000000Z", "wall_time": "2025-12-22T15:40:00Z", "close": 4427.93, "ema": 4423.55262950025, "ref_price": 4425.51, "buy_wall": 4440.0, "retests_buy": 4, "retests_required": 5, "break_buffer": 0.2, "min_ema_dist": 0.5, "max_wall_distance": 12.0, "reason": "EVAL", "mwd_ok": false, "ret_ok": false, "broken_down": true, "trend_ok": false, "dist_ref_to_wall": 14.489999999999782, "schema_version": 1}
{"event": "SHORT_CHECK", "dt_utc": "2025-12-22T16:00:09Z", "candle_time": "2025-12-22T15:44:00.000000000Z", "wall_time": "2025-12-22T15:40:00Z", "close": 4427.89, "ema": 4423.946935909318, "ref_price": 4425.51, "buy_wall": 4440.0, "retests_buy": 5, "retests_required": 5, "break_buffer": 0.2, "min_ema_dist": 0.5, "max_wall_distance": 12.0, "reason": "EVAL", "mwd_ok": false, "ret_ok": true, "broken_down": true, "trend_ok": false, "dist_ref_to_wall": 14.489999999999782, "schema_version": 1}
{"event": "SHORT_CHECK", "dt_utc": "2025-12-22T16:00:09Z", "candle_time": "2025-12-22T15:45:00.000000000Z", "wall_time": "2025-12-22T15:40:00Z", "close": 4430.76, "ema": 4424.566305372107, "ref_price": 4425.51, "buy_wall": 4440.0, "retests_buy": 6, "retests_required": 5, "break_buffer": 0.2, "min_ema_dist": 0.5, "max_wall_distance": 12.0, "reason": "EVAL", "mwd_ok": false, "ret_ok": true, "broken_down": true, "trend_ok": false, "dist_ref_to_wall": 14.489999999999782, "schema_version": 1}
{"event": "SHORT_CHECK", "dt_utc": "2025-12-22T16:00:09Z", "candle_time": "2025-12-22T15:46:00.000000000Z", "wall_time": "2025-12-22T15:40:00Z", "close": 4430.52, "ema": 4425.107550338279, "ref_price": 4425.51, "buy_wall": 4440.0, "retests_buy": 7, "retests_required": 5, "break_buffer": 0.2, "min_ema_dist": 0.5, "max_wall_distance": 12.0, "reason": "EVAL", "mwd_ok": false, "ret_ok": true, "broken_down": true, "trend_ok": false, "dist_ref_to_wall": 14.489999999999782, "schema_version": 1}
{"event": "SHORT_CHECK", "dt_utc": "2025-12-22T16:00:09Z", "candle_time": "2025-12-22T15:47:00.000000000Z", "wall_time": "2025-12-22T15:40:00Z", "close": 4428.99, "ema": 4425.460500307526, "ref_price": 4425.51, "buy_wall": 4440.0, "retests_buy": 8, "retests_required": 5, "break_buffer": 0.2, "min_ema_dist": 0.5, "max_wall_distance": 12.0, "reason": "EVAL", "mwd_ok": false, "ret_ok": true, "broken_down": true, "trend_ok": false, "dist_ref_to_wall": 14.489999999999782, "schema_version": 1}
{"event": "SHORT_CHECK", "dt_utc": "2025-12-22T16:00:09Z", "candle_time": "2025-12-22T15:48:00.000000000Z", "wall_time": "2025-12-22T15:40:00Z", "close": 4431.055, "ema": 4425.96909118866, "ref_price": 4425.51, "buy_wall": 4440.0, "retests_buy": 9, "retests_required": 5, "break_buffer": 0.2, "min_ema_dist": 0.5, "max_wall_distance": 12.0, "reason": "EVAL", "mwd_ok": false, "ret_ok": true, "broken_down": true, "trend_ok": false, "dist_ref_to_wall": 14.489999999999782, "schema_version": 1}
{"event": "SHORT_CHECK", "dt_utc": "2025-12-22T16:00:09Z", "candle_time": "2025-12-22T15:49:00.000000000Z", "wall_time": "2025-12-22T15:40:00Z", "close": 4431.035, "ema": 4426.429628353328, "ref_price": 4425.51, "buy_wall": 4440.0, "retests_buy": 10, "retests_required": 5, "break_buffer": 0.2, "min_ema_dist": 0.5, "max_wall_distance": 12.0, "reason": "EVAL", "mwd_ok": false, "ret_ok": true, "broken_down": true, "trend_ok": false, "dist_ref_to_wall": 14.489999999999782, "schema_version": 1}
{"event": "SHORT_CHECK", "dt_utc": "2025-12-22T16:00:09Z", "candle_time": "2025-12-22T15:50:00.000000000Z", "wall_time": "2025-12-22T15:40:00Z", "close": 4430.63, "ema": 4426.8114803212075, "ref_price": 4425.51, "buy_wall": 4440.0, "retests_buy": 11, "retests_required": 5, "break_buffer": 0.2, "min_ema_dist": 0.5, "max_wall_distance": 12.0, "reason": "EVAL", "mwd_ok": false, "ret_ok": true, "broken_down": true, "trend_ok": false, "dist_ref_to_wall": 14.489999999999782, "schema_version": 1}
{"event": "SHORT_CHECK", "dt_utc": "2025-12-22T16:00:09Z", "candle_time": "2025-12-22T15:51:00.000000000Z", "wall_time": "2025-12-22T15:40:00Z", "close": 4431.385, "ema": 4427.227254837461, "ref_price": 4425.51, "buy_wall": 4440.0, "retests_buy": 12, "retests_required": 5, "break_buffer": 0.2, "min_ema_dist": 0.5, "max_wall_distance": 12.0, "reason": "EVAL", "mwd_ok": false, "ret_ok": true, "broken_down": true, "trend_ok": false, "dist_ref_to_wall": 14.489999999999782, "schema_version": 1}
{"event": "SHORT_CHECK", "dt_utc": "2025-12-22T16:00:09Z", "candle_time": "2025-12-22T15:52:00.000000000Z", "wall_time": "2025-12-22T15:40:00Z", "close": 4432.215, "ema": 4427.680686215874, "ref_price": 4425.51, "buy_wall": 4440.0, "retests_buy": 13, "retests_required": 5, "break_buffer": 0.2, "min_ema_dist": 0.5, "max_wall_distance": 12.0, "reason": "EVAL", "mwd_ok": false, "ret_ok": true, "broken_down": true, "trend_ok": false, "dist_ref_to_wall": 14.489999999999782, "schema_version": 1}
{"event": "SHORT_CHECK", "dt_utc": "2025-12-22T16:00:09Z", "candle_time": "2025-12-22T15:53:00.000000000Z", "wall_time": "2025-12-22T15:40:00Z", "close": 4431.77, "ema": 4428.05244201443, "ref_price": 4425.51, "buy_wall": 4440.0, "retests_buy": 14, "retests_required": 5, "break_buffer": 0.2, "min_ema_dist": 0.5, "max_wall_distance": 12.0, "reason": "EVAL", "mwd_ok": false, "ret_ok": true, "broken_down": true, "trend_ok": false, "dist_ref_to_wall": 14.489999999999782, "schema_version": 1}
{"event": "SHORT_CHECK", "dt_utc": "2025-12-22T16:00:09Z", "candle_time": "2025-12-22T15:54:00.000000000Z", "wall_time": "2025-12-22T15:40:00Z", "close": 4431.325, "ema": 4428.349947285846, "ref_price": 4425.51, "buy_wall": 4440.0, "retests_buy": 15, "retests_required": 5, "break_buffer": 0.2, "min_ema_dist": 0.5, "max_wall_distance": 12.0, "reason": "EVAL", "mwd_ok": false, "ret_ok": true, "broken_down": true, "trend_ok": false, "dist_ref_to_wall": 14.489999999999782, "schema_version": 1}
