src/output/live/WBv3_EMA9_TRAIL_LIMITS-XAU_USD/XAU_USD/trades.jsonl
{"event": "STATE_NEW", "note": "no state.json found; starting fresh", "schema_version": 3, "dt_utc": "2026-01-28T16:03:07Z"}
{"event": "BOOKS_SAVED", "book_time": "2026-01-28T16:00:00Z", "ref_price": 5278.28, "buy_wall": null, "sell_wall": 5300.0, "attempts": 1, "schema_version": 3, "dt_utc": "2026-01-28T16:03:07Z"}
{"event": "LIMIT_SKIP_TOO_FAR_FROM_MKT", "book_time": "2026-01-28T16:00:00Z", "side": "short", "wall": 5300.0, "mid": 5277.755, "max_dist": 15.0, "schema_version": 3, "dt_utc": "2026-01-28T16:03:07Z"}
{"event": "BOOKS_SAVED", "book_time": "2026-01-28T16:20:00Z", "ref_price": 5287.595, "buy_wall": null, "sell_wall": 5300.0, "attempts": 1, "schema_version": 3, "dt_utc": "2026-01-28T16:20:06Z"}
{"event": "LIMIT_SKIP_MWD", "book_time": "2026-01-28T16:20:00Z", "side": "short", "wall": 5300.0, "ref_price": 5287.595, "max_wall_distance": 12.0, "schema_version": 3, "dt_utc": "2026-01-28T16:20:06Z"}
{"event": "CANDLES_SAVED", "n_new": 20, "newest": "2026-01-28T16:19:00.000000000Z", "attempts": 1, "schema_version": 3, "dt_utc": "2026-01-28T16:20:08Z"}
{"event": "BOOKS_SAVED", "book_time": "2026-01-28T16:40:00Z", "ref_price": 5283.19, "buy_wall": null, "sell_wall": 5300.0, "attempts": 1, "schema_version": 3, "dt_utc": "2026-01-28T16:40:05Z"}
{"event": "LIMIT_SKIP_TOO_FAR_FROM_MKT", "book_time": "2026-01-28T16:40:00Z", "side": "short", "wall": 5300.0, "mid": 5282.975, "max_dist": 15.0, "schema_version": 3, "dt_utc": "2026-01-28T16:40:05Z"}
{"event": "CANDLES_SAVED", "n_new": 20, "newest": "2026-01-28T16:39:00.000000000Z", "attempts": 1, "schema_version": 3, "dt_utc": "2026-01-28T16:40:08Z"}
{"event": "BOOKS_SAVED", "book_time": "2026-01-28T17:00:00Z", "ref_price": 5299.875, "buy_wall": null, "sell_wall": 5303.0, "attempts": 1, "schema_version": 3, "dt_utc": "2026-01-28T17:00:06Z"}
{"event": "LIMIT_PLACE", "book_time": "2026-01-28T17:00:00Z", "side": "short", "wall": 5303.0, "strength": 0.1248, "entry": 5303.0, "sl": 5304.0, "tp": 5300.5, "vol": 5.0, "ok": true, "res": {"retcode": 10009, "deal": 0, "order": 1434897064, "volume": 5.0, "price": 0.0, "bid": 0.0, "ask": 0.0, "comment": "Request executed", "request_id": 843516986, "retcode_external": 0, "request": [5, 2209001, 0, "XAUUSD", 5.0, 5303.0, 0.0, 5304.0, 5300.5, 15, 3, 2, 0, 0, "WBv3 LIM S XAU_USD", 0, 0]}, "schema_version": 3, "dt_utc": "2026-01-28T17:00:06Z"}
{"event": "CANDLES_SAVED", "n_new": 20, "newest": "2026-01-28T16:59:00.000000000Z", "attempts": 1, "schema_version": 3, "dt_utc": "2026-01-28T17:00:08Z"}
{"event": "REPLAY_BATCH", "note": "processing 20 new candles since 2026-01-28T16:39:00.000000000Z", "schema_version": 3, "dt_utc": "2026-01-28T17:00:08Z"}
{"event": "STRAT_TICK", "candle_time": "2026-01-28T16:59:00.000000000Z", "close": 5299.875, "ema": 5295.266811555329, "atr": 4.52509188194489, "ref_price": 5283.19, "buy_wall": null, "sell_wall": 5300.0, "retests_buy": 0, "retests_sell": 2, "wall_time": "2026-01-28T16:40:00Z", "schema_version": 3, "dt_utc": "2026-01-28T17:00:08Z"}
{"event": "BOOKS_SAVED", "book_time": "2026-01-28T17:20:00Z", "ref_price": 5293.365, "buy_wall": 5310.0, "sell_wall": 5314.5, "attempts": 1, "schema_version": 3, "dt_utc": "2026-01-28T17:20:05Z"}
{"event": "LIMIT_SKIP_TOO_FAR_FROM_MKT", "book_time": "2026-01-28T17:20:00Z", "side": "short", "wall": 5314.5, "mid": 5291.575000000001, "max_dist": 15.0, "schema_version": 3, "dt_utc": "2026-01-28T17:20:05Z"}
{"event": "LIMIT_SKIP_TOO_FAR_FROM_MKT", "book_time": "2026-01-28T17:20:00Z", "side": "long", "wall": 5310.0, "mid": 5291.575000000001, "max_dist": 15.0, "schema_version": 3, "dt_utc": "2026-01-28T17:20:05Z"}
{"event": "CANDLES_SAVED", "n_new": 20, "newest": "2026-01-28T17:19:00.000000000Z", "attempts": 1, "schema_version": 3, "dt_utc": "2026-01-28T17:20:08Z"}
{"event": "REPLAY_BATCH", "note": "processing 20 new candles since 2026-01-28T16:59:00.000000000Z", "schema_version": 3, "dt_utc": "2026-01-28T17:20:08Z"}
{"event": "LONG_CHECK", "candle_time": "2026-01-28T17:01:00.000000000Z", "wall_time": "2026-01-28T17:00:00Z", "close": 5304.77, "ema": 5298.3271593954105, "ref_price": 5299.875, "sell_wall": 5303.0, "retests_sell": 2, "mwd_ok": true, "ret_ok": false, "broken_up": true, "trend_ok": true, "schema_version": 3, "dt_utc": "2026-01-28T17:20:08Z"}
{"event": "LONG_CHECK", "candle_time": "2026-01-28T17:02:00.000000000Z", "wall_time": "2026-01-28T17:00:00Z", "close": 5303.97, "ema": 5299.455727516329, "ref_price": 5299.875, "sell_wall": 5303.0, "retests_sell": 3, "mwd_ok": true, "ret_ok": false, "broken_up": true, "trend_ok": true, "schema_version": 3, "dt_utc": "2026-01-28T17:20:08Z"}
{"event": "LONG_CHECK", "candle_time": "2026-01-28T17:03:00.000000000Z", "wall_time": "2026-01-28T17:00:00Z", "close": 5303.485, "ema": 5300.261582013063, "ref_price": 5299.875, "sell_wall": 5303.0, "retests_sell": 4, "mwd_ok": true, "ret_ok": false, "broken_up": true, "trend_ok": true, "schema_version": 3, "dt_utc": "2026-01-28T17:20:08Z"}
{"event": "LONG_CHECK", "candle_time": "2026-01-28T17:05:00.000000000Z", "wall_time": "2026-01-28T17:00:00Z", "close": 5301.775, "ema": 5300.88641248836, "ref_price": 5299.875, "sell_wall": 5303.0, "retests_sell": 6, "mwd_ok": true, "ret_ok": true, "broken_up": false, "trend_ok": true, "schema_version": 3, "dt_utc": "2026-01-28T17:20:08Z"}
{"event": "LONG_CHECK", "candle_time": "2026-01-28T17:06:00.000000000Z", "wall_time": "2026-01-28T17:00:00Z", "close": 5298.205, "ema": 5300.350129990689, "ref_price": 5299.875, "sell_wall": 5303.0, "retests_sell": 7, "mwd_ok": true, "ret_ok": true, "broken_up": false, "trend_ok": false, "schema_version": 3, "dt_utc": "2026-01-28T17:20:08Z"}
{"event": "LONG_CHECK", "candle_time": "2026-01-28T17:07:00.000000000Z", "wall_time": "2026-01-28T17:00:00Z", "close": 5296.68, "ema": 5299.616103992552, "ref_price": 5299.875, "sell_wall": 5303.0, "retests_sell": 7, "mwd_ok": true, "ret_ok": true, "broken_up": false, "trend_ok": false, "schema_version": 3, "dt_utc": "2026-01-28T17:20:08Z"}
{"event": "LONG_CHECK", "candle_time": "2026-01-28T17:08:00.000000000Z", "wall_time": "2026-01-28T17:00:00Z", "close": 5293.995, "ema": 5298.491883194041, "ref_price": 5299.875, "sell_wall": 5303.0, "retests_sell": 7, "mwd_ok": true, "ret_ok": true, "broken_up": false, "trend_ok": false, "schema_version": 3, "dt_utc": "2026-01-28T17:20:08Z"}
{"event": "LONG_CHECK", "candle_time": "2026-01-28T17:09:00.000000000Z", "wall_time": "2026-01-28T17:00:00Z", "close": 5295.375, "ema": 5297.868506555233, "ref_price": 5299.875, "sell_wall": 5303.0, "retests_sell": 7, "mwd_ok": true, "ret_ok": true, "broken_up": false, "trend_ok": false, "schema_version": 3, "dt_utc": "2026-01-28T17:20:08Z"}
{"event": "LONG_CHECK", "candle_time": "2026-01-28T17:10:00.000000000Z", "wall_time": "2026-01-28T17:00:00Z", "close": 5296.425, "ema": 5297.579805244186, "ref_price": 5299.875, "sell_wall": 5303.0, "retests_sell": 7, "mwd_ok": true, "ret_ok": true, "broken_up": false, "trend_ok": false, "schema_version": 3, "dt_utc": "2026-01-28T17:20:08Z"}
{"event": "LONG_CHECK", "candle_time": "2026-01-28T17:11:00.000000000Z", "wall_time": "2026-01-28T17:00:00Z", "close": 5296.735, "ema": 5297.410844195349, "ref_price": 5299.875, "sell_wall": 5303.0, "retests_sell": 7, "mwd_ok": true, "ret_ok": true, "broken_up": false, "trend_ok": false, "schema_version": 3, "dt_utc": "2026-01-28T17:20:08Z"}
{"event": "LONG_CHECK", "candle_time": "2026-01-28T17:12:00.000000000Z", "wall_time": "2026-01-28T17:00:00Z", "close": 5294.67, "ema": 5296.862675356279, "ref_price": 5299.875, "sell_wall": 5303.0, "retests_sell": 7, "mwd_ok": true, "ret_ok": true, "broken_up": false, "trend_ok": false, "schema_version": 3, "dt_utc": "2026-01-28T17:20:08Z"}
{"event": "LONG_CHECK", "candle_time": "2026-01-28T17:13:00.000000000Z", "wall_time": "2026-01-28T17:00:00Z", "close": 5295.965, "ema": 5296.683140285024, "ref_price": 5299.875, "sell_wall": 5303.0, "retests_sell": 7, "mwd_ok": true, "ret_ok": true, "broken_up": false, "trend_ok": false, "schema_version": 3, "dt_utc": "2026-01-28T17:20:08Z"}
